Workbook

Sheet How to interface with Web tool
A1: Field | B1: Required | C1: Description
A2: id | B2: TRUE | C2: A unique identifier for this aspect. Can be any chain of characters unless the aspect is an input (only letters, underscores and numbers are accepted). Not visible to the end user.
A3: type | B3: TRUE | C3: The row will appear in either the `input` section, general `outputs` or backend depending of the value specified here.
A4: label_en | B4: TRUE | C4: A user visible label in english.
A5: label_fr | B5: TRUE | C5: A user visible label in French
A6: group_name_en | B6: When type is `backend` | C6: Aspects will be grouped under this use visible group name. Use the same group name for multiple aspects to group them together.
A7: group_name_fr | C7: Aspects will be grouped under this use visible group name. Use the same group name for multiple aspects to group them together.
A8: description_en | C8: An optional user visible description. Will appear under the aspect label (and unit, if specified) with a gray tone.
A9: description_fr | C9: An optional user visible description. Will appear under the aspect label (and unit, if specified) with a gray tone.
A10: warning_en | C10: An optional user visible warning. Will appear under the aspect label, unit (if specified) and description (if specified) with a yellow tone.
A11: warning_fr | C11: An optional user visible warning. Will appear under the aspect label, unit (if specified) and description (if specified) with a yellow tone.
A12: is_static | C12: When TRUE, the values for a given aspect will appear within a grayed out box. Use to display constants and other non-variable values (eg. Imports from an external model).
A13: unit | C13: Can be `millions` or `percents`; will be localized to the end user's preference (and multiply values x100 if percents).
A14: [Fiscal years] | C14: A series of fical year columns must be included. Fiscal year headers MUST adopt the following format: `YYYY-YYYY`.
C17: Notes
C18: A `machine_readable` sheet must be present and include the fields above.
C19: The field headers MUST be on row 1.
C20: Empty rows are not allowed.
C21: User inputs should be set to 0 by default.

Sheet machine_readable
A1: id | B1: type | C1: label_en | D1: label_fr | E1: group_name_en | F1: group_name_fr | G1: description_en | H1: description_fr | I1: warning_en | J1: warning_fr | K1: is_static | L1: unit | M1: 2026-2027 | N1: 2027-2028 | O1: 2028-2029 | P1: 2029-2030 | Q1: 2030-2031
A2: total_revenue_measures | B2: input | C2: Total revenues measures | D2: Revenu total provenant de nouvelles mesures | L2: millions | M2: 0 | N2: 0 | O2: 0 | P2: 0 | Q2: 0
A3: total_program_spending_measures | B3: input | C3: Total program spending measures | D3: Dépense totale provenant de nouvelles mesures | L3: millions | M3: 0 | N3: 0 | O3: 0 | P3: 0 | Q3: 0
A4: Net change on primary balance | B4: outputs | C4: Net change on primary balance | D4: Changement net sur le solde primaire | L4: millions | M4: ='For user (EN)'!D6 -> 0 | N4: ='For user (EN)'!E6 -> 0 | O4: ='For user (EN)'!F6 -> 0 | P4: ='For user (EN)'!G6 -> 0 | Q4: ='For user (EN)'!H6 -> 0
A5: Annual public debt charges | B5: outputs | C5: Annual public debt charges | D5: Frais annuels de la dette publique | L5: millions | M5: ='For user (EN)'!D10 -> 0 | N5: ='For user (EN)'!E10 -> 0 | O5: ='For user (EN)'!F10 -> 0 | P5: ='For user (EN)'!G10 -> 0 | Q5: ='For user (EN)'!H10 -> 0
A6: Surplus for the year | B6: outputs | C6: Surplus/(deficit) for the year | D6: Surplus/(déficit) pour l'année | I6: Includes public debt charges on surplus/(deficit) from previous years resulting from the implemented policies. | J6: Inclut le service de la dette publique sur le surplus/(déficit) des années précédentes résultant des politiques mises en œuvre. | L6: millions | M6: ='For user (EN)'!D12 -> 0 | N6: ='For user (EN)'!E12 -> 0 | O6: ='For user (EN)'!F12 -> 0 | P6: ='For user (EN)'!G12 -> 0 | Q6: ='For user (EN)'!H12 -> 0
A7: Cumulative surplus | B7: outputs | C7: Cumulative surplus/(deficit) | D7: Surplus/(déficit) cumulatif | L7: millions | M7: ='For user (EN)'!D11 -> 0 | N7: ='For user (EN)'!E11 -> 0 | O7: ='For user (EN)'!F11 -> 0 | P7: ='For user (EN)'!G11 -> 0 | Q7: ='For user (EN)'!H11 -> 0
A8: Cumulative public debt charges | B8: outputs | C8: Cumulative public debt charges | D8: Frais cumulatifs de la dette publique | L8: millions | M8: ='For user (EN)'!D13 -> 0 | N8: ='For user (EN)'!E13 -> 0 | O8: ='For user (EN)'!F13 -> 0 | P8: ='For user (EN)'!G13 -> 0 | Q8: ='For user (EN)'!H13 -> 0
A9: 90-day treasury bills rate | B9: backend | C9: 90-day treasury bills rate | D9: Taux des bons du Trésor à 90 jours | E9: Interest rates | F9: Taux d'intérêt | K9: TRUE | M9: =Model!E10 -> 2.2 | N9: =Model!F10 -> 2.575 | O9: =Model!G10 -> 2.7 | P9: =Model!H10 -> 2.7 | Q9: =Model!I10 -> 2.7
A10: 2-year bond rate | B10: backend | C10: 2-year bond rate | D10: Taux des obligations à 2 ans | E10: Interest rates | F10: Taux d'intérêt | K10: TRUE | M10: =Model!E13 -> 2.4880752 | N10: =Model!F13 -> 2.7674467 | O10: =Model!G13 -> 2.82 | P10: =Model!H13 -> 2.82 | Q10: =Model!I13 -> 2.82
A11: 3-year bond rate | B11: backend | C11: 3-year bond rate | D11: Taux des obligations à 3 ans | E11: Interest rates | F11: Taux d'intérêt | K11: TRUE | M11: =Model!E14 -> 2.5634454 | N11: =Model!F14 -> 2.8226651 | O11: =Model!G14 -> 2.868 | P11: =Model!H14 -> 2.868 | Q11: =Model!I14 -> 2.868
A12: 5-year bond rate | B12: backend | C12: 5-year bond rate | D12: Taux des obligations à 5 ans | E12: Interest rates | F12: Taux d'intérêt | K12: TRUE | M12: =Model!E15 -> 2.7644324 | N12: =Model!F15 -> 2.9699143 | O12: =Model!G15 -> 2.996 | P12: =Model!H15 -> 2.996 | Q12: =Model!I15 -> 2.996
A13: 10-year bond rate | B13: backend | C13: 10-year bond rate | D13: Taux des obligations à 10 ans | E13: Interest rates | F13: Taux d'intérêt | K13: TRUE | M13: ='Fiscal Model Import'!G14 -> 3.4561688 | N13: ='Fiscal Model Import'!H14 -> 3.4953072 | O13: ='Fiscal Model Import'!I14 -> 3.5 | P13: ='Fiscal Model Import'!J14 -> 3.5 | Q13: ='Fiscal Model Import'!K14 -> 3.5
A14: Long-term bond rate (new borrowing) | B14: backend | C14: Long-term bonds rate | D14: Taux des obligations à long terme | E14: Interest rates | F14: Taux d'intérêt | K14: TRUE | M14: =Model!E12 -> 3.8076797 | N14: =Model!F12 -> 3.7604843 | O14: =Model!G12 -> 3.75 | P14: =Model!H12 -> 3.75 | Q14: =Model!I12 -> 3.75
A15: Marginal effective interest rate (all new debt) | B15: backend | C15: Marginal effective interest rate | D15: Taux d'intérêt marginal effectif | E15: Interest rates | F15: Taux d'intérêt | K15: TRUE | M15: =Model!E17 -> 2.6580714 | N15: =Model!F17 -> 2.8980501 | O15: =Model!G17 -> 2.9683549 | P15: =Model!H17 -> 2.9683549 | Q15: =Model!I17 -> 2.9683549
A16: Interest on primary balances | B16: backend | C16: Interest on surplus/(deficit) | D16: Intérêt sur le surplus/(déficit) | E16: Overall new debt | F16: Nouvelle dette globale | M16: =SUM(Model!E20,Model!E21) -> 0 | N16: =SUM(Model!F20,Model!F21) -> 0 | O16: =SUM(Model!G20,Model!G21) -> 0 | P16: =SUM(Model!H20,Model!H21) -> 0 | Q16: =SUM(Model!I20,Model!I21) -> 0
A17: New financing requirement | B17: backend | C17: New financing requirement | D17: Nouveau besoin de financement | E17: Overall new debt | F17: Nouvelle dette globale | M17: =Model!E22 -> 0 | N17: =Model!F22 -> 0 | O17: =Model!G22 -> 0 | P17: =Model!H22 -> 0 | Q17: =Model!I22 -> 0
A18: Outstanding debt | B18: backend | C18: Outstanding debt | D18: Encours de la dette | E18: Overall new debt | F18: Nouvelle dette globale | M18: =Model!E23 -> 0 | N18: =Model!F23 -> 0 | O18: =Model!G23 -> 0 | P18: =Model!H23 -> 0 | Q18: =Model!I23 -> 0
A19: Treasury bills issuance | B19: backend | C19: Treasury bills issuance | D19: Émissions de bons du trésor | E19: Public debt composition | F19: Composition de la dette publique | M19: =Model!E26 -> 0 | N19: =Model!F26 -> 0 | O19: =Model!G26 -> 0 | P19: =Model!H26 -> 0 | Q19: =Model!I26 -> 0
A20: Medium-term bonds issuance | B20: backend | C20: Medium-term bonds issuance | D20: Émissions d'obligations à moyen terme | E20: Public debt composition | F20: Composition de la dette publique | M20: =Model!E30 -> 0 | N20: =Model!F30 -> 0 | O20: =Model!G30 -> 0 | P20: =Model!H30 -> 0 | Q20: =Model!I30 -> 0
A21: Long-term bonds issuance | B21: backend | C21: Long-term bonds issuance | D21: Émissions d'obligations à long terme | E21: Public debt composition | F21: Composition de la dette publique | M21: =Model!E31 -> 0 | N21: =Model!F31 -> 0 | O21: =Model!G31 -> 0 | P21: =Model!H31 -> 0 | Q21: =Model!I31 -> 0
A22: Treasury bills expiring | B22: backend | C22: Treasury bills expiring | D22: Échéances des bons du trésor | E22: Public debt composition | F22: Composition de la dette publique | M22: =Model!E33 -> 0 | N22: =Model!F33 -> 0 | O22: =Model!G33 -> 0 | P22: =Model!H33 -> 0 | Q22: =Model!I33 -> 0
A23: Medium-term bonds expiring | B23: backend | C23: Medium-term bonds expiring | D23: Échéances des obligations à moyen terme | E23: Public debt composition | F23: Composition de la dette publique | M23: =Model!E37 -> 0 | N23: =Model!F37 -> 0 | O23: =Model!G37 -> 0 | P23: =Model!H37 -> 0 | Q23: =Model!I37 -> 0
A24: T-bills outstanding | B24: backend | C24: Treasury bills outstanding | D24: Encours des bons du Trésor | E24: Public debt composition | F24: Composition de la dette publique | M24: =Model!E39 -> 0 | N24: =Model!F39 -> 0 | O24: =Model!G39 -> 0 | P24: =Model!H39 -> 0 | Q24: =Model!I39 -> 0
A25: Medium-term bonds outstanding | B25: backend | C25: Medium-term bonds outstanding | D25: Encours des obligations à moyen terme | E25: Public debt composition | F25: Composition de la dette publique | M25: =Model!E43 -> 0 | N25: =Model!F43 -> 0 | O25: =Model!G43 -> 0 | P25: =Model!H43 -> 0 | Q25: =Model!I43 -> 0
A26: Long-term bond outstanding | B26: backend | C26: Long-term bonds outstanding | D26: Encours des obligations à long terme | E26: Public debt composition | F26: Composition de la dette publique | M26: =Model!E44 -> 0 | N26: =Model!F44 -> 0 | O26: =Model!G44 -> 0 | P26: =Model!H44 -> 0 | Q26: =Model!I44 -> 0

Sheet For user (EN)
A1: Fiscal year | D1: 2026 | E1: =D1+1 -> 2027 | F1: =E1+1 -> 2028 | G1: =F1+1 -> 2029 | H1: =G1+1 -> 2030
D2: 2027 | E2: =D2+1 -> 2028 | F2: =E2+1 -> 2029 | G2: =F2+1 -> 2030 | H2: =G2+1 -> 2031
A3: INPUTS
A4: Total revenues measures | B4: $ million | D4: =machine_readable!M2 -> 0 | E4: =machine_readable!N2 -> 0 | F4: =machine_readable!O2 -> 0 | G4: =machine_readable!P2 -> 0 | H4: =machine_readable!Q2 -> 0
A5: Total program spending measures | B5: $ million | D5: =machine_readable!M3 -> 0 | E5: =machine_readable!N3 -> 0 | F5: =machine_readable!O3 -> 0 | G5: =machine_readable!P3 -> 0 | H5: =machine_readable!Q3 -> 0
A6: Net change on primary balance | B6: $ million | D6: =D4-D5 -> 0 | E6: =E4-E5 -> 0 | F6: =F4-F5 -> 0 | G6: =G4-G5 -> 0 | H6: =H4-H5 -> 0
A9: OUTPUT
A10: Annual public debt charges | B10: $ million | D10: =Model!E53 -> 0 | E10: =Model!F53 -> 0 | F10: =Model!G53 -> 0 | G10: =Model!H53 -> 0 | H10: =Model!I53 -> 0
A11: Cumulative surplus | B11: $ million | D11: =Model!E54 -> 0 | E11: =Model!F54 -> 0 | F11: =Model!G54 -> 0 | G11: =Model!H54 -> 0 | H11: =Model!I54 -> 0
A12: Surplus for the year* | B12: $ million | D12: =Model!E53+Model!E6 -> 0 | E12: =Model!F53+Model!F6 -> 0 | F12: =Model!G53+Model!G6 -> 0 | G12: =Model!H53+Model!H6 -> 0 | H12: =Model!I53+Model!I6 -> 0
A13: Cumulative public debt charges | B13: $ million | D13: =SUM($C10:D10) -> 0 | E13: =SUM($C10:E10) -> 0 | F13: =SUM($C10:F10) -> 0 | G13: =SUM($C10:G10) -> 0 | H13: =SUM($C10:H10) -> 0
A15: *Equals net change in primary balance + annual public debt charges. Includes debt charges on deficits/surplus from previous years resulting from policies implemented by the party platform

Sheet Model
A1: Fiscal year | D1: 2025 | E1: =D1+1 -> 2026 | F1: =E1+1 -> 2027 | G1: =F1+1 -> 2028 | H1: =G1+1 -> 2029 | I1: =H1+1 -> 2030
D2: 2026 | E2: =D2+1 -> 2027 | F2: =E2+1 -> 2028 | G2: =F2+1 -> 2029 | H2: =G2+1 -> 2030 | I2: =H2+1 -> 2031
A3: INPUTS | B3: Rationale
A4: Total revenues measures | C4: $ million | D4: ='For user (EN)'!C4 -> 0 | E4: ='For user (EN)'!D4 -> 0 | F4: ='For user (EN)'!E4 -> 0 | G4: ='For user (EN)'!F4 -> 0 | H4: ='For user (EN)'!G4 -> 0 | I4: ='For user (EN)'!H4 -> 0
A5: Total program spending measures | C5: $ million | D5: ='For user (EN)'!C5 -> 0 | E5: ='For user (EN)'!D5 -> 0 | F5: ='For user (EN)'!E5 -> 0 | G5: ='For user (EN)'!F5 -> 0 | H5: ='For user (EN)'!G5 -> 0 | I5: ='For user (EN)'!H5 -> 0
A6: Net change on primary balance | C6: $ million | D6: ='For user (EN)'!C6 -> 0 | E6: ='For user (EN)'!D6 -> 0 | F6: ='For user (EN)'!E6 -> 0 | G6: ='For user (EN)'!F6 -> 0 | H6: ='For user (EN)'!G6 -> 0 | I6: ='For user (EN)'!H6 -> 0
A8: Back-end
A9: Fiscal Model Imports
A10: 90-day treasury bills rate | B10: From fiscal model | D10: ='Fiscal Model Import'!F12 -> 2.4220834 | E10: ='Fiscal Model Import'!G12 -> 2.2 | F10: ='Fiscal Model Import'!H12 -> 2.575 | G10: ='Fiscal Model Import'!I12 -> 2.7 | H10: ='Fiscal Model Import'!J12 -> 2.7 | I10: ='Fiscal Model Import'!K12 -> 2.7
A11: MT bond rate (new borrowing) | B11: Calculated from fiscal model outputs | D11: ='Fiscal Model Import'!F20 -> 2.9513889 | E11: ='Fiscal Model Import'!G20 -> 2.6044361 | F11: ='Fiscal Model Import'!H20 -> 2.8517559 | G11: ='Fiscal Model Import'!I20 -> 2.8932879 | H11: ='Fiscal Model Import'!J20 -> 2.8932879 | I11: ='Fiscal Model Import'!K20 -> 2.8932879
A12: Long-term bond rate (new borrowing) | B12: From fiscal model | D12: ='Fiscal Model Import'!F13 -> 3.7068182 | E12: ='Fiscal Model Import'!G13 -> 3.8076797 | F12: ='Fiscal Model Import'!H13 -> 3.7604843 | G12: ='Fiscal Model Import'!I13 -> 3.75 | H12: ='Fiscal Model Import'!J13 -> 3.75 | I12: ='Fiscal Model Import'!K13 -> 3.75
A13: 2Y bond rate (new borrowing) | B13: From fiscal model | D13: ='Fiscal Model Import'!F16 -> 2.9513889 | E13: ='Fiscal Model Import'!G16 -> 2.4880752 | F13: ='Fiscal Model Import'!H16 -> 2.7674467 | G13: ='Fiscal Model Import'!I16 -> 2.82 | H13: ='Fiscal Model Import'!J16 -> 2.82 | I13: ='Fiscal Model Import'!K16 -> 2.82
A14: 3Y bond rate (new borrowing) | B14: From fiscal model | D14: ='Fiscal Model Import'!F17 -> 2.9513889 | E14: ='Fiscal Model Import'!G17 -> 2.5634454 | F14: ='Fiscal Model Import'!H17 -> 2.8226651 | G14: ='Fiscal Model Import'!I17 -> 2.868 | H14: ='Fiscal Model Import'!J17 -> 2.868 | I14: ='Fiscal Model Import'!K17 -> 2.868
A15: 5Y bond rate (new borrowing) | B15: From fiscal model | D15: ='Fiscal Model Import'!F18 -> 2.9513889 | E15: ='Fiscal Model Import'!G18 -> 2.7644324 | F15: ='Fiscal Model Import'!H18 -> 2.9699143 | G15: ='Fiscal Model Import'!I18 -> 2.996 | H15: ='Fiscal Model Import'!J18 -> 2.996 | I15: ='Fiscal Model Import'!K18 -> 2.996
A16: 10Y bond rate (new borrowing) | B16: From fiscal model | D16: ='Fiscal Model Import'!F14 -> 3.3042592 | E16: ='Fiscal Model Import'!G14 -> 3.4561688 | F16: ='Fiscal Model Import'!H14 -> 3.4953072 | G16: ='Fiscal Model Import'!I14 -> 3.5 | H16: ='Fiscal Model Import'!J14 -> 3.5 | I16: ='Fiscal Model Import'!K14 -> 3.5
A17: Marginal effective interest rate (all new debt) | B17: Calculated from fiscal model outputs | D17: ='Fiscal Model Import'!F21 -> 2.8419066 | E17: ='Fiscal Model Import'!G21 -> 2.6580714 | F17: ='Fiscal Model Import'!H21 -> 2.8980501 | G17: ='Fiscal Model Import'!I21 -> 2.9683549 | H17: ='Fiscal Model Import'!J21 -> 2.9683549 | I17: ='Fiscal Model Import'!K21 -> 2.9683549
A19: Overall New Debt
A20: Interest on primary balances | B20: Primary balance * marginal eff. Int. rate | D20: =SUM('Model Quarterly'!D19:G20) -> 0 | E20: =SUM('Model Quarterly'!H19:K19) -> 0 | F20: =SUM('Model Quarterly'!L19:O19) -> 0 | G20: =SUM('Model Quarterly'!P19:S19) -> 0 | H20: =SUM('Model Quarterly'!T19:W19) -> 0 | I20: =SUM('Model Quarterly'!X19:AA19) -> 0
A21: Interest on existing cumulative surplus/deficit | B21: Previous debt stock * running int. rate | D21: =D53-D20 -> 0 | E21: =E53-E20 -> 0 | F21: =F53-F20 -> 0 | G21: =G53-G20 -> 0 | H21: =H53-H20 -> 0 | I21: =I53-I20 -> 0
A22: New financing requirement | B22: Primary balance + debt charges on primary balance + debt charges on existing debt stock | D22: =-(D6+D20+D21) -> 0 | E22: =-(E6+E20+E21) -> 0 | F22: =-(F6+F20+F21) -> 0 | G22: =-(G6+G20+G21) -> 0 | H22: =-(H6+H20+H21) -> 0 | I22: =-(I6+I20+I21) -> 0
A23: Outstanding debt | B23: Sum of previous new borrowings (if there is a cumulative deficit), otherwize zero | D23: =MAX(0,D54*-1) -> 0 | E23: =MAX(0,E54*-1) -> 0 | F23: =MAX(0,F54*-1) -> 0 | G23: =MAX(0,G54*-1) -> 0 | H23: =MAX(0,H54*-1) -> 0 | I23: =MAX(0,I54*-1) -> 0
A25: Government Bonds Composition (Isssuance & Stock)
A26: T-bills issuance | B26: (New borrowing requirement + total expiring debt) * share of T-bills | D26: =SUM('Model Quarterly'!D28:G28) -> 0 | E26: =SUM('Model Quarterly'!H28:K28) -> 0 | F26: =SUM('Model Quarterly'!L28:O28) -> 0 | G26: =SUM('Model Quarterly'!P28:S28) -> 0 | H26: =SUM('Model Quarterly'!T28:W28) -> 0 | I26: =SUM('Model Quarterly'!X28:AA28) -> 0
A27: 2Y bonds issuance | B27: (New borrowing requirement + total expiring debt) * share of 2Y bonds | D27: =SUM('Model Quarterly'!D29:G29) -> 0 | E27: =SUM('Model Quarterly'!H29:K29) -> 0 | F27: =SUM('Model Quarterly'!L29:O29) -> 0 | G27: =SUM('Model Quarterly'!P29:S29) -> 0 | H27: =SUM('Model Quarterly'!T29:W29) -> 0 | I27: =SUM('Model Quarterly'!X29:AA29) -> 0
A28: 3Y bonds issuance | B28: (New borrowing requirement + total expiring debt) * share of 3Y bonds | D28: =SUM('Model Quarterly'!D30:G30) -> 0 | E28: =SUM('Model Quarterly'!H30:K30) -> 0 | F28: =SUM('Model Quarterly'!L30:O30) -> 0 | G28: =SUM('Model Quarterly'!P30:S30) -> 0 | H28: =SUM('Model Quarterly'!T30:W30) -> 0 | I28: =SUM('Model Quarterly'!X30:AA30) -> 0
A29: 5Y bonds issuance | B29: (New borrowing requirement + total expiring debt) * share of 5Y bonds | D29: =SUM('Model Quarterly'!D31:G31) -> 0 | E29: =SUM('Model Quarterly'!H31:K31) -> 0 | F29: =SUM('Model Quarterly'!L31:O31) -> 0 | G29: =SUM('Model Quarterly'!P31:S31) -> 0 | H29: =SUM('Model Quarterly'!T31:W31) -> 0 | I29: =SUM('Model Quarterly'!X31:AA31) -> 0
A30: MT bonds issuance | B30: Sum of 2Y, 3Y, 5Y issuances | D30: =SUM(D27:D29) -> 0 | E30: =SUM(E27:E29) -> 0 | F30: =SUM(F27:F29) -> 0 | G30: =SUM(G27:G29) -> 0 | H30: =SUM(H27:H29) -> 0 | I30: =SUM(I27:I29) -> 0
A31: LT bonds issuance | B31: (New borrowing requirement + total expiring debt) * share of LT bonds | D31: =SUM('Model Quarterly'!D32:G32) -> 0 | E31: =SUM('Model Quarterly'!H32:K32) -> 0 | F31: =SUM('Model Quarterly'!L32:O32) -> 0 | G31: =SUM('Model Quarterly'!P32:S32) -> 0 | H31: =SUM('Model Quarterly'!T32:W32) -> 0 | I31: =SUM('Model Quarterly'!X32:AA32) -> 0
A33: T-bills expiration | B33: Issuance in previous period | D33: =SUM('Model Quarterly'!D55:G55) -> 0 | E33: =SUM('Model Quarterly'!H55:K55) -> 0 | F33: =SUM('Model Quarterly'!L55:O55) -> 0 | G33: =SUM('Model Quarterly'!P55:S55) -> 0 | H33: =SUM('Model Quarterly'!T55:W55) -> 0 | I33: =SUM('Model Quarterly'!X55:AA55) -> 0
A34: 2Y bonds expiration | B34: Issuance 2y ago | D34: =SUM('Model Quarterly'!D56:G56) -> 0 | E34: =SUM('Model Quarterly'!H56:K56) -> 0 | F34: =SUM('Model Quarterly'!L56:O56) -> 0 | G34: =SUM('Model Quarterly'!P56:S56) -> 0 | H34: =SUM('Model Quarterly'!T56:W56) -> 0 | I34: =SUM('Model Quarterly'!X56:AA56) -> 0
A35: 3Y bonds expiration | B35: Issuance 3y ago | D35: =SUM('Model Quarterly'!D57:G57) -> 0 | E35: =SUM('Model Quarterly'!H57:K57) -> 0 | F35: =SUM('Model Quarterly'!L57:O57) -> 0 | G35: =SUM('Model Quarterly'!P57:S57) -> 0 | H35: =SUM('Model Quarterly'!T57:W57) -> 0 | I35: =SUM('Model Quarterly'!X57:AA57) -> 0
A36: 5Y bonds expiration | B36: Issuance 5y ago | D36: =SUM('Model Quarterly'!D58:G58) -> 0 | E36: =SUM('Model Quarterly'!H58:K58) -> 0 | F36: =SUM('Model Quarterly'!L58:O58) -> 0 | G36: =SUM('Model Quarterly'!P58:S58) -> 0 | H36: =SUM('Model Quarterly'!T58:W58) -> 0 | I36: =SUM('Model Quarterly'!X58:AA58) -> 0
A37: MT bonds expiration | B37: Sum of 2Y, 3Y, 5Y expirations | D37: =SUM('Model Quarterly'!D59:G59) -> 0 | E37: =SUM('Model Quarterly'!H59:K59) -> 0 | F37: =SUM('Model Quarterly'!L59:O59) -> 0 | G37: =SUM('Model Quarterly'!P59:S59) -> 0 | H37: =SUM('Model Quarterly'!T59:W59) -> 0 | I37: =SUM('Model Quarterly'!X59:AA59) -> 0
A39: T-bills outstanding | B39: Equal to current year issuance | D39: ='Model Quarterly'!G36 -> 0 | E39: ='Model Quarterly'!K36 -> 0 | F39: ='Model Quarterly'!O36 -> 0 | G39: ='Model Quarterly'!S36 -> 0 | H39: ='Model Quarterly'!W36 -> 0 | I39: ='Model Quarterly'!AA36 -> 0
A40: 2Y bonds: outstanding | B40: Previous year stock + this year issuance - this year expiring | D40: ='Model Quarterly'!G37 -> 0 | E40: ='Model Quarterly'!K37 -> 0 | F40: ='Model Quarterly'!O37 -> 0 | G40: ='Model Quarterly'!S37 -> 0 | H40: ='Model Quarterly'!W37 -> 0 | I40: ='Model Quarterly'!AA37 -> 0
A41: 3Y bonds: outstanding | B41: Previous year stock + this year issuance - this year expiring | D41: ='Model Quarterly'!G38 -> 0 | E41: ='Model Quarterly'!K38 -> 0 | F41: ='Model Quarterly'!O38 -> 0 | G41: ='Model Quarterly'!S38 -> 0 | H41: ='Model Quarterly'!W38 -> 0 | I41: ='Model Quarterly'!AA38 -> 0
A42: 5Y bonds: outstanding | B42: Previous year stock + this year issuance - this year expiring | D42: ='Model Quarterly'!G39 -> 0 | E42: ='Model Quarterly'!K39 -> 0 | F42: ='Model Quarterly'!O39 -> 0 | G42: ='Model Quarterly'!S39 -> 0 | H42: ='Model Quarterly'!W39 -> 0 | I42: ='Model Quarterly'!AA39 -> 0
A43: Medium-term bonds outstanding | B43: Sum of 2Y, 3Y, 5Y Stocks | D43: ='Model Quarterly'!G40 -> 0 | E43: ='Model Quarterly'!K40 -> 0 | F43: ='Model Quarterly'!O40 -> 0 | G43: ='Model Quarterly'!S40 -> 0 | H43: ='Model Quarterly'!W40 -> 0 | I43: ='Model Quarterly'!AA40 -> 0
A44: Long-term bond stock | B44: Previous year stock + this year issuance - this year expiring | D44: ='Model Quarterly'!G41 -> 0 | E44: ='Model Quarterly'!K41 -> 0 | F44: ='Model Quarterly'!O41 -> 0 | G44: ='Model Quarterly'!S41 -> 0 | H44: ='Model Quarterly'!W41 -> 0 | I44: ='Model Quarterly'!AA41 -> 0
A45: Stock percentage: T-bills | B45: T-bills stock / total debt stock | D45: =IF(D23=0,0,D39/D23) -> 0 | E45: =IF(E23=0,0,E39/E23) -> 0 | F45: =IF(F23=0,0,F39/F23) -> 0 | G45: =IF(G23=0,0,G39/G23) -> 0 | H45: =IF(H23=0,0,H39/H23) -> 0 | I45: =IF(I23=0,0,I39/I23) -> 0
...

Sheet Model Quarterly
A1: Fiscal year | D1: 2025 | E1: 2025 | F1: 2025 | G1: 2025 | H1: 2026 | I1: 2026 | J1: 2026 | K1: 2026 | L1: 2027 | M1: 2027 | N1: 2027 | O1: 2027 | P1: 2028 | Q1: 2028 | R1: 2028 | S1: 2028 | T1: 2029 | U1: 2029 | V1: 2029 | W1: 2029 | X1: 2030 | Y1: 2030 | Z1: 2030 | AA1: 2030
D2: 2026 | E2: 2026 | F2: 2026 | G2: 2026 | H2: 2027 | I2: 2027 | J2: 2027 | K2: 2027 | L2: 2028 | M2: 2028 | N2: 2028 | O2: 2028 | P2: 2029 | Q2: 2029 | R2: 2029 | S2: 2029 | T2: 2030 | U2: 2030 | V2: 2030 | W2: 2030 | X2: 2031 | Y2: 2031 | Z2: 2031 | AA2: 2031
A3: Quarter | D3: 2025Q2 | E3: 2025Q3 | F3: 2025Q4 | G3: 2026Q1 | H3: 2026Q2 | I3: 2026Q3 | J3: 2026Q4 | K3: 2027Q1 | L3: 2027Q2 | M3: 2027Q3 | N3: 2027Q4 | O3: 2028Q1 | P3: 2028Q2 | Q3: 2028Q3 | R3: 2028Q4 | S3: 2029Q1 | T3: 2029Q2 | U3: 2029Q3 | V3: 2029Q4 | W3: 2030Q1 | X3: 2030Q2 | Y3: 2029Q3 | Z3: 2029Q4 | AA3: 2030Q1
A4: INPUTS | B4: Rationale
A5: Total revenues measures | C5: $ million | D5: ='For user (EN)'!C4/4 -> 0 | E5: ='For user (EN)'!C4/4 -> 0 | F5: ='For user (EN)'!C4/4 -> 0 | G5: ='For user (EN)'!C4/4 -> 0 | H5: ='For user (EN)'!D4/4 -> 0 | I5: ='For user (EN)'!$D4/4 -> 0 | J5: ='For user (EN)'!$D4/4 -> 0 | K5: ='For user (EN)'!$D4/4 -> 0 | L5: ='For user (EN)'!$E4/4 -> 0 | M5: ='For user (EN)'!$E4/4 -> 0 | N5: ='For user (EN)'!$E4/4 -> 0 | O5: ='For user (EN)'!$E4/4 -> 0 | P5: ='For user (EN)'!$F4/4 -> 0 | Q5: ='For user (EN)'!$F4/4 -> 0 | R5: ='For user (EN)'!$F4/4 -> 0 | S5: ='For user (EN)'!$F4/4 -> 0 | T5: ='For user (EN)'!$G4/4 -> 0 | U5: ='For user (EN)'!$G4/4 -> 0 | V5: ='For user (EN)'!$G4/4 -> 0 | W5: ='For user (EN)'!$G4/4 -> 0 | X5: ='For user (EN)'!$G4/4 -> 0 | Y5: ='For user (EN)'!$G4/4 -> 0 | Z5: ='For user (EN)'!$G4/4 -> 0 | AA5: ='For user (EN)'!$G4/4 -> 0
A6: Total program spending measures | C6: $ million | D6: ='For user (EN)'!C5/4 -> 0 | E6: ='For user (EN)'!C5/4 -> 0 | F6: ='For user (EN)'!C5/4 -> 0 | G6: ='For user (EN)'!C5/4 -> 0 | H6: ='For user (EN)'!D5/4 -> 0 | I6: ='For user (EN)'!$D5/4 -> 0 | J6: ='For user (EN)'!$D5/4 -> 0 | K6: ='For user (EN)'!$D5/4 -> 0 | L6: ='For user (EN)'!$E5/4 -> 0 | M6: ='For user (EN)'!$E5/4 -> 0 | N6: ='For user (EN)'!$E5/4 -> 0 | O6: ='For user (EN)'!$E5/4 -> 0 | P6: ='For user (EN)'!$F5/4 -> 0 | Q6: ='For user (EN)'!$F5/4 -> 0 | R6: ='For user (EN)'!$F5/4 -> 0 | S6: ='For user (EN)'!$F5/4 -> 0 | T6: ='For user (EN)'!$G5/4 -> 0 | U6: ='For user (EN)'!$G5/4 -> 0 | V6: ='For user (EN)'!$G5/4 -> 0 | W6: ='For user (EN)'!$G5/4 -> 0 | X6: ='For user (EN)'!$H5/4 -> 0 | Y6: ='For user (EN)'!$H5/4 -> 0 | Z6: ='For user (EN)'!$H5/4 -> 0 | AA6: ='For user (EN)'!$H5/4 -> 0
A7: Net change on primary balance | C7: $ million | D7: ='For user (EN)'!C6/4 -> 0 | E7: ='For user (EN)'!C6/4 -> 0 | F7: ='For user (EN)'!C6/4 -> 0 | G7: ='For user (EN)'!C6/4 -> 0 | H7: ='For user (EN)'!D6/4 -> 0 | I7: ='For user (EN)'!$D6/4 -> 0 | J7: ='For user (EN)'!$D6/4 -> 0 | K7: ='For user (EN)'!$D6/4 -> 0 | L7: ='For user (EN)'!$E6/4 -> 0 | M7: ='For user (EN)'!$E6/4 -> 0 | N7: ='For user (EN)'!$E6/4 -> 0 | O7: ='For user (EN)'!$E6/4 -> 0 | P7: ='For user (EN)'!$F6/4 -> 0 | Q7: ='For user (EN)'!$F6/4 -> 0 | R7: ='For user (EN)'!$F6/4 -> 0 | S7: ='For user (EN)'!$F6/4 -> 0 | T7: ='For user (EN)'!$G6/4 -> 0 | U7: ='For user (EN)'!$G6/4 -> 0 | V7: ='For user (EN)'!$G6/4 -> 0 | W7: ='For user (EN)'!$G6/4 -> 0 | X7: ='For user (EN)'!$H6/4 -> 0 | Y7: ='For user (EN)'!$H6/4 -> 0 | Z7: ='For user (EN)'!$H6/4 -> 0 | AA7: ='For user (EN)'!$H6/4 -> 0
A9: Back-end
A10: Fiscal Model Imports
A11: 90-day treasury bills rate | B11: From fiscal model | D11: ='Fiscal Model Import'!O31 -> 2.6616667 | E11: ='Fiscal Model Import'!P31 -> 2.596 | F11: ='Fiscal Model Import'!Q31 -> 2.246 | G11: ='Fiscal Model Import'!R31 -> 2.184667 | H11: ='Fiscal Model Import'!S31 -> 2.2 | I11: ='Fiscal Model Import'!T31 -> 2.2 | J11: ='Fiscal Model Import'!U31 -> 2.2 | K11: ='Fiscal Model Import'!V31 -> 2.2 | ... AA11: ='Fiscal Model Import'!AL31 -> 2.7
A12: Long-term bond rate (new borrowing) | B12: From fiscal model | D12: ='Fiscal Model Import'!O29 -> 3.53 | E12: ='Fiscal Model Import'!P29 -> 3.7833333 | F12: ='Fiscal Model Import'!Q29 -> 3.6766667 | G12: ='Fiscal Model Import'!R29 -> 3.837273 | H12: ='Fiscal Model Import'!S29 -> 3.825513 | I12: ='Fiscal Model Import'!T29 -> 3.813624 | J12: ='Fiscal Model Import'!U29 -> 3.801735 | K12: ='Fiscal Model Import'!V29 -> 3.789847 | ... AA12: ='Fiscal Model Import'!AL29 -> 3.75
A13: 2Y bond rate (new borrowing) | B13: From fiscal model | D13: ='Fiscal Model Import'!O32 -> 2.9906667 | E13: ='Fiscal Model Import'!P32 -> 3.0644 | F13: ='Fiscal Model Import'!Q32 -> 2.8384 | G13: ='Fiscal Model Import'!R32 -> 2.912089 | H13: ='Fiscal Model Import'!S32 -> 2.4156075 | I13: ='Fiscal Model Import'!T32 -> 2.4483044 | J13: ='Fiscal Model Import'!U32 -> 2.5111633 | K13: ='Fiscal Model Import'!V32 -> 2.5772257 | ... AA13: ='Fiscal Model Import'!AL32 -> 2.82
A14: 3Y bond rate (new borrowing) | B14: From fiscal model | D14: ='Fiscal Model Import'!O33 -> 2.9906667 | E14: ='Fiscal Model Import'!P33 -> 3.0644 | F14: ='Fiscal Model Import'!Q33 -> 2.8384 | G14: ='Fiscal Model Import'!R33 -> 2.912089 | H14: ='Fiscal Model Import'!S33 -> 2.4898505 | I14: ='Fiscal Model Import'!T33 -> 2.5232987 | J14: ='Fiscal Model Import'!U33 -> 2.5869092 | K14: ='Fiscal Model Import'!V33 -> 2.6537231 | ... AA14: ='Fiscal Model Import'!AL33 -> 2.868
A15: 5Y bond rate (new borrowing) | B15: From fiscal model | D15: ='Fiscal Model Import'!O34 -> 2.9906667 | E15: ='Fiscal Model Import'!P34 -> 3.0644 | F15: ='Fiscal Model Import'!Q34 -> 2.8384 | G15: ='Fiscal Model Import'!R34 -> 2.912089 | H15: ='Fiscal Model Import'!S34 -> 2.6878316 | I15: ='Fiscal Model Import'!T34 -> 2.7232835 | J15: ='Fiscal Model Import'!U34 -> 2.7888982 | K15: ='Fiscal Model Import'!V34 -> 2.8577162 | ... AA15: ='Fiscal Model Import'!AL34 -> 2.996
A16: Marginal effective interest rate (all new debt) | B16: Calculated from fiscal model outputs | D16: ='Fiscal Model Import'!O42 -> 2.9356926 | E16: ='Fiscal Model Import'!P42 -> 2.9769656 | F16: ='Fiscal Model Import'!Q42 -> 2.7145156 | G16: ='Fiscal Model Import'!R42 -> 2.7404523 | H16: ='Fiscal Model Import'!S42 -> 2.6154788 | I16: ='Fiscal Model Import'!T42 -> 2.6246963 | J16: ='Fiscal Model Import'!U42 -> 2.6441179 | K16: ='Fiscal Model Import'!V42 -> 2.6646235 | ... AA16: ='Fiscal Model Import'!AL42 -> 2.9618806
A18: Overall New Debt
A19: Interest on primary balances | B19: Primary balance * marginal eff. Int. rate | D19: =(D16/100)*D7/4 -> 0 | E19: =(E16/100)*E7/4 -> 0 | F19: =(F16/100)*F7/4 -> 0 | G19: =(G16/100)*G7/4 -> 0 | H19: =(H16/100)*H7/4 -> 0 | I19: =(I16/100)*I7/4 -> 0 | J19: =(J16/100)*J7/4 -> 0 | K19: =(K16/100)*K7/4 -> 0 | ... AA19: =(AA16/100)*AA7/4 -> 0
A20: Interest on existing cumulative surplus/deficit | B20: Previous debt stock * running int. rate | D20: =(C71/100)*C75/4 -> 0 | E20: =(D71/100)*D75/4 -> 0 | F20: =(E71/100)*E75/4 -> 0 | G20: =(F71/100)*F75/4 -> 0 | H20: =(G71/100)*G75/4 -> 0 | I20: =(H71/100)*H75/4 -> 0 | J20: =(I71/100)*I75/4 -> 0 | K20: =(J71/100)*J75/4 -> 0 | ... AA20: =(Z71/100)*Z75/4 -> 0
A21: New financing requirement | B21: Primary balance + debt charges on primary balance + debt charges on existing debt stock | D21: =-(D7+D19+D20) -> 0 | E21: =-(E7+E19+E20) -> 0 | F21: =-(F7+F19+F20) -> 0 | G21: =-(G7+G19+G20) -> 0 | H21: =-(H7+H19+H20) -> 0 | I21: =-(I7+I19+I20) -> 0 | J21: =-(J7+J19+J20) -> 0 | K21: =-(K7+K19+K20) -> 0 | ... AA21: =-(AA7+AA19+AA20) -> 0
A22: Outstanding debt | B22: Sum of previous new borrowings (if there is a cumulative deficit), otherwize zero | D22: =MAX(0,SUM($D21:D21)) -> 0 | E22: =MAX(0,SUM($D21:E21)) -> 0 | F22: =MAX(0,SUM($D21:F21)) -> 0 | G22: =MAX(0,SUM($D21:G21)) -> 0 | H22: =MAX(0,SUM($D21:H21)) -> 0 | I22: =MAX(0,SUM($D21:I21)) -> 0 | J22: =MAX(0,SUM($D21:J21)) -> 0 | K22: =MAX(0,SUM($D21:K21)) -> 0 | ... AA22: =MAX(0,SUM($D21:AA21)) -> 0
A24: Government Bonds Composition (Isssuance & Stock)
A25: 3 months T-bills: issuance | B25: (New borrowing requirement + total expiring debt) * share of T-bills | D25: =IF(D$22>0,MIN(MAX(SUM(D$21,D$55,D$59),0),D$22)*'Fiscal Model Import'!O44,0) -> 0 | E25: =IF(E$22>0,MIN(MAX(SUM(E$21,E$55,E$59),0),E$22)*'Fiscal Model Import'!P44,0) -> 0 | F25: =IF(F$22>0,MIN(MAX(SUM(F$21,F$55,F$59),0),F$22)*'Fiscal Model Import'!Q44,0) -> 0 | G25: =IF(G$22>0,MIN(MAX(SUM(G$21,G$55,G$59),0),G$22)*'Fiscal Model Import'!R44,0) -> 0 | H25: =IF(H$22>0,MIN(MAX(SUM(H$21,H$55,H$59),0),H$22)*'Fiscal Model Import'!S44,0) -> 0 | I25: =IF(I$22>0,MIN(MAX(SUM(I$21,I$55,I$59),0),I$22)*'Fiscal Model Import'!T44,0) -> 0 | J25: =IF(J$22>0,MIN(MAX(SUM(J$21,J$55,J$59),0),J$22)*'Fiscal Model Import'!U44,0) -> 0 | K25: =IF(K$22>0,MIN(MAX(SUM(K$21,K$55,K$59),0),K$22)*'Fiscal Model Import'!V44,0) -> 0 | ... AA25: =IF(AA$22>0,MIN(MAX(SUM(AA$21,AA$55,AA$59),0),AA$22)*'Fiscal Model Import'!AL44,0) -> 0
A28: Total T-bills: issuance | B28: Sum of 3m, 6m, 1y T-bills | D28: =SUM(D25:D27) -> 0 | E28: =SUM(E25:E27) -> 0 | F28: =SUM(F25:F27) -> 0 | G28: =SUM(G25:G27) -> 0 | H28: =SUM(H25:H27) -> 0 | I28: =SUM(I25:I27) -> 0 | J28: =SUM(J25:J27) -> 0 | K28: =SUM(K25:K27) -> 0 | ... AA28: =SUM(AA25:AA27) -> 0
A29: 2 Year Bonds: issuance | B29: (New borrowing requirement + total expiring debt) * share of 2Y bonds | D29: =IF(D22>0,MIN(D22,MAX(0,SUM(D$21,D$55,D$59)))*'Fiscal Model Import'!O38,0) -> 0 | E29: =IF(E22>0,MIN(E22,MAX(0,SUM(E$21,E$55,E$59)))*'Fiscal Model Import'!P38,0) -> 0 | F29: =IF(F22>0,MIN(F22,MAX(0,SUM(F$21,F$55,F$59)))*'Fiscal Model Import'!Q38,0) -> 0 | G29: =IF(G22>0,MIN(G22,MAX(0,SUM(G$21,G$55,G$59)))*'Fiscal Model Import'!R38,0) -> 0 | H29: =IF(H22>0,MIN(H22,MAX(0,SUM(H$21,H$55,H$59)))*'Fiscal Model Import'!S38,0) -> 0 | I29: =IF(I22>0,MIN(I22,MAX(0,SUM(I$21,I$55,I$59)))*'Fiscal Model Import'!T38,0) -> 0 | J29: =IF(J22>0,MIN(J22,MAX(0,SUM(J$21,J$55,J$59)))*'Fiscal Model Import'!U38,0) -> 0 | K29: =IF(K22>0,MIN(K22,MAX(0,SUM(K$21,K$55,K$59)))*'Fiscal Model Import'!V38,0) -> 0 | ... AA29: =IF(AA22>0,MIN(AA22,MAX(0,SUM(AA$21,AA$55,AA$59)))*'Fiscal Model Import'!AL38,0) -> 0
A30: 3 Year Bonds: issuance | B30: (New borrowing requirement + total expiring debt) * share of 3Y bonds | D30: =IF(D22>0,MIN(D22,MAX(SUM(D$21,D$55,D$59),0))*'Fiscal Model Import'!O39,0) -> 0 | E30: =IF(E22>0,MIN(E22,MAX(SUM(E$21,E$55,E$59),0))*'Fiscal Model Import'!P39,0) -> 0 | F30: =IF(F22>0,MIN(F22,MAX(SUM(F$21,F$55,F$59),0))*'Fiscal Model Import'!Q39,0) -> 0 | G30: =IF(G22>0,MIN(G22,MAX(SUM(G$21,G$55,G$59),0))*'Fiscal Model Import'!R39,0) -> 0 | H30: =IF(H22>0,MIN(H22,MAX(SUM(H$21,H$55,H$59),0))*'Fiscal Model Import'!S39,0) -> 0 | I30: =IF(I22>0,MIN(I22,MAX(SUM(I$21,I$55,I$59),0))*'Fiscal Model Import'!T39,0) -> 0 | J30: =IF(J22>0,MIN(J22,MAX(SUM(J$21,J$55,J$59),0))*'Fiscal Model Import'!U39,0) -> 0 | K30: =IF(K22>0,MIN(K22,MAX(SUM(K$21,K$55,K$59),0))*'Fiscal Model Import'!V39,0) -> 0 | ... AA30: =IF(AA22>0,MIN(AA22,MAX(SUM(AA$21,AA$55,AA$59),0))*'Fiscal Model Import'!AL39,0) -> 0
A31: 5 Year Bonds: issuance | B31: (New borrowing requirement + total expiring debt) * share of 5Y bonds | D31: =IF(D22>0,MIN(D22,MAX(SUM(D$21,D$55,D$59),0))*'Fiscal Model Import'!O40,0) -> 0 | E31: =IF(E22>0,MIN(E22,MAX(SUM(E$21,E$55,E$59),0))*'Fiscal Model Import'!P40,0) -> 0 | F31: =IF(F22>0,MIN(F22,MAX(SUM(F$21,F$55,F$59),0))*'Fiscal Model Import'!Q40,0) -> 0 | G31: =IF(G22>0,MIN(G22,MAX(SUM(G$21,G$55,G$59),0))*'Fiscal Model Import'!R40,0) -> 0 | H31: =IF(H22>0,MIN(H22,MAX(SUM(H$21,H$55,H$59),0))*'Fiscal Model Import'!S40,0) -> 0 | I31: =IF(I22>0,MIN(I22,MAX(SUM(I$21,I$55,I$59),0))*'Fiscal Model Import'!T40,0) -> 0 | J31: =IF(J22>0,MIN(J22,MAX(SUM(J$21,J$55,J$59),0))*'Fiscal Model Import'!U40,0) -> 0 | K31: =IF(K22>0,MIN(K22,MAX(SUM(K$21,K$55,K$59),0))*'Fiscal Model Import'!V40,0) -> 0 | ... AA31: =IF(AA22>0,MIN(AA22,MAX(SUM(AA$21,AA$55,AA$59),0))*'Fiscal Model Import'!AL40,0) -> 0
A32: Long-term bonds: issuance | B32: (New borrowing requirement + total expiring debt) * share of LT bonds | D32: =IF(D22>0,MIN(D22,MAX(0,SUM(D21,D55,D59)))*'Fiscal Model Import'!O36,0) -> 0 | E32: =IF(E22>0,MIN(E22,MAX(0,SUM(E21,E55,E59)))*'Fiscal Model Import'!P36,0) -> 0 | F32: =IF(F22>0,MIN(F22,MAX(0,SUM(F21,F55,F59)))*'Fiscal Model Import'!Q36,0) -> 0 | G32: =IF(G22>0,MIN(G22,MAX(0,SUM(G21,G55,G59)))*'Fiscal Model Import'!R36,0) -> 0 | H32: =IF(H22>0,MIN(H22,MAX(0,SUM(H21,H55,H59)))*'Fiscal Model Import'!S36,0) -> 0 | I32: =IF(I22>0,MIN(I22,MAX(0,SUM(I21,I55,I59)))*'Fiscal Model Import'!T36,0) -> 0 | J32: =IF(J22>0,MIN(J22,MAX(0,SUM(J21,J55,J59)))*'Fiscal Model Import'!U36,0) -> 0 | K32: =IF(K22>0,MIN(K22,MAX(0,SUM(K21,K55,K59)))*'Fiscal Model Import'!V36,0) -> 0 | ... AA32: =IF(AA22>0,MIN(AA22,MAX(0,SUM(AA21,AA55,AA59)))*'Fiscal Model Import'!AL36,0) -> 0
A33: 3 months T-bills: outstanding | B33: Same as current period issuance | D33: =D25 -> 0 | E33: =E25 -> 0 | F33: =F25 -> 0 | G33: =G25 -> 0 | H33: =H25 -> 0 | I33: =I25 -> 0 | J33: =J25 -> 0 | K33: =K25 -> 0 | ... AA33: =AA25 -> 0
A36: Total T-bills outstanding | B36: Sum of 3m, 6m, 1y T-bills outstanding | D36: =SUM(D33:D35) -> 0 | E36: =SUM(E33:E35) -> 0 | F36: =SUM(F33:F35) -> 0 | G36: =SUM(G33:G35) -> 0 | H36: =SUM(H33:H35) -> 0 | I36: =SUM(I33:I35) -> 0 | J36: =SUM(J33:J35) -> 0 | K36: =SUM(K33:K35) -> 0 | ... AA36: =SUM(AA33:AA35) -> 0
A37: 2Y bonds: outstanding | B37: Previous period stock + this year issuance - this year expiring | D37: =D29 -> 0 | E37: =IF(AND(E$22>0,E$21+E$55+E$59>0),D37+E29-E56,E$22*D46) -> 0 | F37: =IF(AND(F$22>0,F$21+F$55+F$59>0),E37+F29-F56,F$22*E46) -> 0 | G37: =IF(AND(G$22>0,G$21+G$55+G$59>0),F37+G29-G56,G$22*F46) -> 0 | H37: =IF(AND(H$22>0,H$21+H$55+H$59>0),G37+H29-H56,H$22*G46) -> 0 | I37: =IF(AND(I$22>0,I$21+I$55+I$59>0),H37+I29-I56,I$22*H46) -> 0 | J37: =IF(AND(J$22>0,J$21+J$55+J$59>0),I37+J29-J56,J$22*I46) -> 0 | K37: =IF(AND(K$22>0,K$21+K$55+K$59>0),J37+K29-K56,K$22*J46) -> 0 | L37: =IF(AND(L$22>0,L$21+L$55+L$59>0),K37+L29-L56,L$22*K46) -> 0 | ... AA37: =IF(AND(AA$22>0,AA$21+AA$55+AA$59>0),Z37+AA29-AA56,AA$22*Z46) -> 0
A38: 3Y bonds: outstanding | B38: Previous period stock + this year issuance - this year expiring | D38: =D30 -> 0 | E38: =IF(AND(E$22>0,E$21+E$55+E$59>0),D38+E30-E57,E$22*D47) -> 0 | F38: =IF(AND(F$22>0,F$21+F$55+F$59>0),E38+F30-F57,F$22*E47) -> 0 | G38: =IF(AND(G$22>0,G$21+G$55+G$59>0),F38+G30-G57,G$22*F47) -> 0 | H38: =IF(AND(H$22>0,H$21+H$55+H$59>0),G38+H30-H57,H$22*G47) -> 0 | I38: =IF(AND(I$22>0,I$21+I$55+I$59>0),H38+I30-I57,I$22*H47) -> 0 | J38: =IF(AND(J$22>0,J$21+J$55+J$59>0),I38+J30-J57,J$22*I47) -> 0 | K38: =IF(AND(K$22>0,K$21+K$55+K$59>0),J38+K30-K57,K$22*J47) -> 0 | L38: =IF(AND(L$22>0,L$21+L$55+L$59>0),K38+L30-L57,L$22*K47) -> 0 | ... AA38: =IF(AND(AA$22>0,AA$21+AA$55+AA$59>0),Z38+AA30-AA57,AA$22*Z47) -> 0
A39: 5Y bonds: outstanding | B39: Previous period stock + this year issuance - this year expiring | D39: =D31 -> 0 | E39: =IF(AND(E$22>0,E$21+E$55+E$59>0),D39+E31-E58,E$22*D48) -> 0 | F39: =IF(AND(F$22>0,F$21+F$55+F$59>0),E39+F31-F58,F$22*E48) -> 0 | G39: =IF(AND(G$22>0,G$21+G$55+G$59>0),F39+G31-G58,G$22*F48) -> 0 | H39: =IF(AND(H$22>0,H$21+H$55+H$59>0),G39+H31-H58,H$22*G48) -> 0 | I39: =IF(AND(I$22>0,I$21+I$55+I$59>0),H39+I31-I58,I$22*H48) -> 0 | J39: =IF(AND(J$22>0,J$21+J$55+J$59>0),I39+J31-J58,J$22*I48) -> 0 | K39: =IF(AND(K$22>0,K$21+K$55+K$59>0),J39+K31-K58,K$22*J48) -> 0 | L39: =IF(AND(L$22>0,L$21+L$55+L$59>0),K39+L31-L58,L$22*K48) -> 0 | ... AA39: =IF(AND(AA$22>0,AA$21+AA$55+AA$59>0),Z39+AA31-AA58,AA$22*Z48) -> 0
A40: Medium-term bonds outstanding | B40: Sum of 2Y, 3Y, 5Y Stocks | D40: =SUM(D37:D39) -> 0 | E40: =SUM(E37:E39) -> 0 | F40: =SUM(F37:F39) -> 0 | G40: =SUM(G37:G39) -> 0 | H40: =SUM(H37:H39) -> 0 | I40: =SUM(I37:I39) -> 0 | J40: =SUM(J37:J39) -> 0 | K40: =SUM(K37:K39) -> 0 | ... AA40: =SUM(AA37:AA39) -> 0
A41: Long-term bond stock | B41: Previous year stock + this year issuance - this year expiring | D41: =D32 -> 0 | E41: =IF(AND(E$22>0,E$21+E$55+E$59>0),D41+E32,E$22*D49) -> 0 | F41: =IF(AND(F$22>0,F$21+F$55+F$59>0),E41+F32,F$22*E49) -> 0 | G41: =IF(AND(G$22>0,G$21+G$55+G$59>0),F41+G32,G$22*F49) -> 0 | H41: =IF(AND(H$22>0,H$21+H$55+H$59>0),G41+H32,H$22*G49) -> 0 | I41: =IF(AND(I$22>0,I$21+I$55+I$59>0),H41+I32,I$22*H49) -> 0 | J41: =IF(AND(J$22>0,J$21+J$55+J$59>0),I41+J32,J$22*I49) -> 0 | K41: =IF(AND(K$22>0,K$21+K$55+K$59>0),J41+K32,K$22*J49) -> 0 | L41: =IF(AND(L$22>0,L$21+L$55+L$59>0),K41+L32,L$22*K49) -> 0 | ... AA41: =IF(AND(AA$22>0,AA$21+AA$55+AA$59>0),Z41+AA32,AA$22*Z49) -> 0
A42: Stock percentage: 3 month T-bills | B42: 3 month T-bills stock / total debt stock | D42: =IF(D$22=0,0,D33/D$22) -> 0 | E42: =IF(E$22=0,0,E33/E$22) -> 0 | F42: =IF(F$22=0,0,F33/F$22) -> 0 | G42: =IF(G$22=0,0,G33/G$22) -> 0 | H42: =IF(H$22=0,0,H33/H$22) -> 0 | I42: =IF(I$22=0,0,I33/I$22) -> 0 | J42: =IF(J$22=0,0,J33/J$22) -> 0 | K42: =IF(K$22=0,0,K33/K$22) -> 0 | ... AA42: =IF(AA$22=0,0,AA33/AA$22) -> 0
A46: Stock percentage: 2Y bonds | B46: 2Y bond stock / total debt stock | D46: =IF(D$22=0,0,D37/D$22) -> 0 | E46: =IF(E$22=0,0,E37/E$22) -> 0 | F46: =IF(F$22=0,0,F37/F$22) -> 0 | G46: =IF(G$22=0,0,G37/G$22) -> 0 | H46: =IF(H$22=0,0,H37/H$22) -> 0 | I46: =IF(I$22=0,0,I37/I$22) -> 0 | J46: =IF(J$22=0,0,J37/J$22) -> 0 | K46: =IF(K$22=0,0,K37/K$22) -> 0 | ... AA46: =IF(AA$22=0,0,AA37/AA$22) -> 0
A47: Stock percentage: 3Y bonds | B47: 3Y bond stock / total debt stock | D47: =IF(D$22=0,0,D38/D$22) -> 0 | E47: =IF(E$22=0,0,E38/E$22) -> 0 | F47: =IF(F$22=0,0,F38/F$22) -> 0 | G47: =IF(G$22=0,0,G38/G$22) -> 0 | H47: =IF(H$22=0,0,H38/H$22) -> 0 | I47: =IF(I$22=0,0,I38/I$22) -> 0 | J47: =IF(J$22=0,0,J38/J$22) -> 0 | K47: =IF(K$22=0,0,K38/K$22) -> 0 | ... AA47: =IF(AA$22=0,0,AA38/AA$22) -> 0
A48: Stock percentage: 5Y bonds | B48: 5Y bond stock / total debt stock | D48: =IF(D$22=0,0,D39/D$22) -> 0 | E48: =IF(E$22=0,0,E39/E$22) -> 0 | F48: =IF(F$22=0,0,F39/F$22) -> 0 | G48: =IF(G$22=0,0,G39/G$22) -> 0 | H48: =IF(H$22=0,0,H39/H$22) -> 0 | I48: =IF(I$22=0,0,I39/I$22) -> 0 | J48: =IF(J$22=0,0,J39/J$22) -> 0 | K48: =IF(K$22=0,0,K39/K$22) -> 0 | ... AA48: =IF(AA$22=0,0,AA39/AA$22) -> 0
A49: Stock percentage: Long-term bonds | B49: LT bond stock / total debt stock | D49: =IF(D22=0,0,D41/D22) -> 0 | E49: =IF(E22=0,0,E41/E22) -> 0 | F49: =IF(F22=0,0,F41/F22) -> 0 | G49: =IF(G22=0,0,G41/G22) -> 0 | H49: =IF(H22=0,0,H41/H22) -> 0 | I49: =IF(I22=0,0,I41/I22) -> 0 | J49: =IF(J22=0,0,J41/J22) -> 0 | K49: =IF(K22=0,0,K41/K22) -> 0 | ... AA49: =IF(AA22=0,0,AA41/AA22) -> 0
A51: Debt Expiring Amounts
...

Sheet Decomposition
A1: Overall Composition | B1: 2021-22 | C1: 2022-23 | D1: 2023-24 | G1: Shares | H1: 2021-22 | I1: 2022-23 | J1: 2023-24 | K1: 2024-25 | L1: 2025-26 | M1: 2026-27 | N1: Post 2026-27
A2: T-bills | B2: =B22 -> 187 | C2: =C22 -> 202 | D2: 281 | G2: T-bills | H2: =B2/B30 -> 0.42117117 | I2: =C2/C30 -> 0.52196382 | J2: =D2/SUM(D$2:D$4) -> 0.57938144 | K2: =J29 -> 0.54597701 | L2: =J30 -> 0.47429519 | M2: =J31 -> 0.45500849 | N2: =AVERAGE(L2:M2) -> 0.46465184
A3: Medium-term Bonds | B3: =SUM(B23:B25) -> 140 | C3: =SUM(C23:C25) -> 118 | D3: =SUM(D23:D25) -> 139 | G3: Medium-term Bonds | H3: =B3/B30 -> 0.31531532 | I3: =C3/C30 -> 0.30490956 | J3: =D3/SUM(D$2:D$4) -> 0.28659794 | K3: =SUM(F37:F39)*K$6 -> 0.29577431 | L3: =SUM(G37:G39)*L$6 -> 0.33830846 | M3: =SUM(H37:H39)*M$6 -> 0.34747781 | N3: =AVERAGE(L3:M3) -> 0.34289313
A4: Long-term Bonds | B4: =SUM(B26:B28) -> 112 | C4: =SUM(C26:C28) -> 66 | D4: =SUM(D26:D28) -> 65 | G4: Long-term Bonds | H4: =1-H2-H3 -> 0.26351351 | I4: =C4/C30 -> 0.17054264 | J4: =D4/SUM(D$2:D$4) -> 0.13402062 | K4: =F40*K$6 -> 0.15824868 | L4: =G40*L$6 -> 0.18739635 | M4: =H40*M$6 -> 0.1975137 | N4: =AVERAGE(L4:M4) -> 0.19245503
M5: =SUM(M2:M4) -> 1 | N5: =SUM(N2:N4) -> 1
G6: Total Bonds | H6: =1-H2 -> 0.57882883 | I6: =1-I2 -> 0.47803618 | J6: =1-J2 -> 0.42061856 | K6: =1-K2 -> 0.45402299 | L6: =1-L2 -> 0.52570481 | M6: =1-M2 -> 0.54499151 | N6: =AVERAGE(L6:M6) -> 0.53534816
A9: Medium Term Bonds Composition (volume) | I9: Medium Term Bonds Composition (percentage)
A10: Bond type | B10: 2021-22 | C10: 2022-23 | D10: 2023-24 | E10: 2024-25 | F10: 2025-26 | G10: 2026-27 | I10: Bond type | J10: share (2021-22) | K10: Share (2022-23) | L10: Share (2023-24) | M10: Share 2024-25 | N10: Share 2025-26 | O10: Share 2026-27 | P10: Share Post 2026-27
A11: 2-Year | B11: =B23 -> 67 | C11: =C23 -> 67 | D11: =D23 -> 86 | E11: =E23 -> 94 | F11: =F23 -> 120 | G11: =G23 -> 110 | I11: 2-Year | J11: =B11/SUM(B$11:B$13) -> 0.47857143 | K11: =C11/SUM(C$11:C$13) -> 0.56779661 | L11: =D11/SUM(D$11:D$13) -> 0.61870504 | M11: =E11/SUM(E$11:E$13) -> 0.59872611 | N11: =F11/SUM(F$11:F$13) -> 0.58823529 | O11: =G11/SUM(G$11:G$13) -> 0.57894737 | P11: =AVERAGE(N11:O11) -> 0.58359133
A12: 3-Year | B12: =B24 -> 29 | C12: =C24 -> 20 | D12: =D24 -> 6 | E12: =E24 -> 0 | F12: =F24 -> 0 | G12: =G24 -> 0 | I12: 3-Year | J12: =B12/SUM(B$11:B$13) -> 0.20714286 | K12: =C12/SUM(C$11:C$13) -> 0.16949153 | L12: =D12/SUM(D$11:D$13) -> 0.043165468 | M12: =E12/SUM(E$11:E$13) -> 0 | N12: =F12/SUM(F$11:F$13) -> 0 | O12: =G12/SUM(G$11:G$13) -> 0 | P12: =AVERAGE(N12:O12) -> 0
A13: 5-Year | B13: =B25 -> 44 | C13: =C25 -> 31 | D13: =D25 -> 47 | E13: =E25 -> 63 | F13: =F25 -> 84 | G13: =G25 -> 80 | I13: 5-Year | J13: =B13/SUM(B$11:B$13) -> 0.31428571 | K13: =C13/SUM(C$11:C$13) -> 0.26271186 | L13: =D13/SUM(D$11:D$13) -> 0.3381295 | M13: =E13/SUM(E$11:E$13) -> 0.40127389 | N13: =F13/SUM(F$11:F$13) -> 0.41176471 | O13: =G13/SUM(G$11:G$13) -> 0.42105263 | P13: =AVERAGE(N13:O13) -> 0.41640867
I16: Historical T-bill Issuance Shares | L16: Historical T-bill Stock Shares (End of Fiscal Year)
I17: 2012-13 | J17: =159/260 -> 0.61153846 | L17: 2012-13 | M17: 0.27050898
I18: 2013-14 | J18: =149/238 -> 0.62605042 | L18: 2013-14 | M18: 0.23585633
B19: 2021-22 | C19: 2022-23 | D19: 2023-24 | E19: 2024-25 | F19: 2025-26 | G19: 2026-27 | I19: 2014-15 | J19: =130/226 -> 0.57522124 | L19: 2014-15 | M19: 0.20892995
B20: Actual | C20: Estimated | D20: Actual | E20: Actual | F20: Estimate | G20: Projected | I20: 2015-16 | J20: =129/221 -> 0.58371041 | L20: 2015-16 | M20: 0.20620373
I21: 2016-17 | J21: =134/268 -> 0.5 | L21: 2016-17 | M21: 0.19665613
A22: Treasury bills | B22: 187 | C22: 202 | D22: 267 | E22: 285 | F22: 286 | G22: 268 | I22: 2017-18 | J22: =131/274 -> 0.47810219 | L22: 2017-18 | M22: 0.15717667
A23: 2-year | B23: 67 | C23: 67 | D23: 86 | E23: 94 | F23: 120 | G23: 110 | I23: 2018-19 | J23: 0.573 | L23: 2018-19 | M23: 0.18624995
A24: 3-year | B24: 29 | C24: 20 | D24: 6 | E24: 0 | F24: 0 | G24: 0 | I24: 2019-20 | J24: =152/279 -> 0.54480287 | L24: 2019-20 | M24: 0.19847511
A25: 5-year | B25: 44 | C25: 31 | D25: 47 | E25: 63 | F25: 84 | G25: 80 | I25: 2020-21 | J25: =219/593 -> 0.3693086 | L25: 2020-21 | M25: 0.1971514
A26: 10-year | B26: 79 | C26: 52 | D26: 47 | E26: 63 | F26: 84 | G26: 80 | I26: 2021-22 | J26: =187/444 -> 0.42117117 | L26: 2021-22 | M26: 0.15202056
A27: 30-year | B27: 28 | C27: 14 | D27: 14 | E27: 17 | F27: 24 | G27: 24 | I27: 2022-23 | J27: =202/387 -> 0.52196382 | L27: 2022-23 | M27: 0.16064935
A28: Green bonds | B28: 5 | C28: - | D28: 4 | E28: 4 | F28: 5 | G28: 4 | I28: 2023-24 | J28: =D22/D30 -> 0.56687898
A29: Total bonds | B29: 258 | C29: 185 | D29: 204 | E29: 241 | F29: 317 | G29: 298 | I29: 2024-25 | J29: =E22/SUM(E22:E27) -> 0.54597701
A30: Total gross issuance | B30: 444 | C30: 387 | D30: 471 | E30: 526 | F30: 603 | G30: 589 | I30: 2025-26 | J30: =F22/F30 -> 0.47429519
I31: 2026-27 | J31: =G22/G30 -> 0.45500849
I32: Average | J32: =AVERAGE(J29:J31) -> 0.49176023
A36: Shares | B36: 2020-21 | C36: 21-22 | D36: 22-23 | E36: 23-24 | F36: 24-25 | G36: 25-26 | H36: Post 25-26
A37: 2-year | B37: 0.34491979 | C37: 0.2627451 | D37: 0.36413043 | E37: =D23/D29 -> 0.42156863 | F37: =E23/E29 -> 0.39004149 | G37: =F23/F29 -> 0.3785489 | H37: =G23/G29 -> 0.36912752
A38: 3-year | B38: 0.14973262 | C38: 0.11372549 | D38: 0.10869565 | E38: =D24/D29 -> 0.029411765 | F38: =E24/E29 -> 0 | G38: =F24/F29 -> 0 | H38: =G24/G29 -> 0
A39: 5-year | B39: 0.21925134 | C39: 0.15686275 | D39: 0.16847826 | E39: =D25/D29 -> 0.23039216 | F39: =E25/E29 -> 0.26141079 | G39: =F25/F29 -> 0.26498423 | H39: =G25/G29 -> 0.26845638
A40: LT | B40: 0.28609626 | C40: 0.46666667 | D40: 0.35869565 | E40: =SUM(D26:D28)/D29 -> 0.31862745 | F40: =SUM(E26:E28)/E29 -> 0.34854772 | G40: =SUM(F26:F28)/F29 -> 0.35646688 | H40: =SUM(G26:G28)/G29 -> 0.36241611
E41: =SUM(E37:E40) -> 1 | F41: =SUM(F37:F40) -> 1 | G41: =SUM(G37:G40) -> 1 | H41: =SUM(H37:H40) -> 1
A43: Based on the latest Debt Management Strategy

Sheet Fiscal Model Import
A1: Assumed Market Debt Shares: | B1: 2021-22 | C1: 2022-23 | D1: 2023-24 | E1: 2024-25 | F1: 2025-26 | G1: 2026-27 | H1: 2027-28 | I1: 2028-29 | J1: 2029-30 | K1: 2030-31
A2: T-Bills | B2: =Decomposition!H2 -> 0.42117117 | C2: =Decomposition!I2 -> 0.52196382 | D2: =Decomposition!J2 -> 0.57938144 | E2: =Decomposition!K2 -> 0.54597701 | F2: =Decomposition!L2 -> 0.47429519 | G2: =Decomposition!M2 -> 0.45500849 | H2: =Decomposition!N2 -> 0.46465184 | I2: =H2 -> 0.46465184 | J2: =I2 -> 0.46465184 | K2: =J2 -> 0.46465184
A3: Long-term Bonds | B3: =Decomposition!H4 -> 0.26351351 | C3: =Decomposition!I4 -> 0.17054264 | D3: =Decomposition!J4 -> 0.13402062 | E3: =Decomposition!K4 -> 0.15824868 | F3: =Decomposition!L4 -> 0.18739635 | G3: =Decomposition!M4 -> 0.1975137 | H3: =Decomposition!N4 -> 0.19245503 | I3: =H3 -> 0.19245503 | J3: =I3 -> 0.19245503 | K3: =J3 -> 0.19245503
A4: Medium-term Bonds | B4: =Decomposition!H3 -> 0.31531532 | C4: =Decomposition!I3 -> 0.30490956 | D4: =Decomposition!J3 -> 0.28659794 | E4: =Decomposition!K3 -> 0.29577431 | F4: =Decomposition!L3 -> 0.33830846 | G4: =Decomposition!M3 -> 0.34747781 | H4: =Decomposition!N3 -> 0.34289313 | I4: =H4 -> 0.34289313 | J4: =I4 -> 0.34289313 | K4: =J4 -> 0.34289313
A6: Medium-term Bond Breakdown | B6: 2021-22 | C6: 2022-23 | D6: 2023-24 | E6: 2024-25 | F6: 2025-26 | G6: 2026-27 | H6: 2027-28 | I6: 2028-29 | J6: 2029-30 | K6: 2030-31
A7: 2-year | B7: =Decomposition!J11 -> 0.47857143 | C7: =Decomposition!K11 -> 0.56779661 | D7: =Decomposition!L11 -> 0.61870504 | E7: =Decomposition!M11 -> 0.59872611 | F7: =Decomposition!N11 -> 0.58823529 | G7: =Decomposition!O11 -> 0.57894737 | H7: =Decomposition!P11 -> 0.58359133 | I7: =H7 -> 0.58359133 | J7: =I7 -> 0.58359133 | K7: =J7 -> 0.58359133
A8: 3-year | B8: =Decomposition!J12 -> 0.20714286 | C8: =Decomposition!K12 -> 0.16949153 | D8: =Decomposition!L12 -> 0.043165468 | E8: =Decomposition!M12 -> 0 | F8: =Decomposition!N12 -> 0 | G8: =Decomposition!O12 -> 0 | H8: =Decomposition!P12 -> 0 | I8: =H8 -> 0 | J8: =I8 -> 0 | K8: =J8 -> 0
A9: 5-year | B9: =Decomposition!J13 -> 0.31428571 | C9: =Decomposition!K13 -> 0.26271186 | D9: =Decomposition!L13 -> 0.3381295 | E9: =Decomposition!M13 -> 0.40127389 | F9: =Decomposition!N13 -> 0.41176471 | G9: =Decomposition!O13 -> 0.42105263 | H9: =Decomposition!P13 -> 0.41640867 | I9: =H9 -> 0.41640867 | J9: =I9 -> 0.41640867 | K9: =J9 -> 0.41640867
A11: Marginal Interest Rate Projections: | C11: 2022-23 | D11: 2023-24 | E11: 2024-25 | F11: 2025-26 | G11: 2026-27 | H11: 2027-28 | I11: 2028-29 | J11: 2029-30 | K11: 2030-31
A12: Marginal T-Bills Rate | C12: =AVERAGE(C31:F31) -> 3.3884167 | D12: =AVERAGE(G31:J31) -> 4.961 | E12: =AVERAGE(K31:N31) -> 3.8144167 | F12: =AVERAGE(O31:R31) -> 2.4220834 | G12: =AVERAGE(S31:V31) -> 2.2 | H12: =AVERAGE(W31:Z31) -> 2.575 | I12: =AVERAGE(AA31:AD31) -> 2.7 | J12: =AVERAGE(AE31:AH31) -> 2.7 | K12: =AVERAGE(AI31:AL31) -> 2.7
A13: Marginal LT Bonds Rate | C13: =AVERAGE(C29:F29) -> 3.045 | D13: =AVERAGE(G29:J29) -> 3.3325 | E13: =AVERAGE(K29:N29) -> 3.3425 | F13: =AVERAGE(O29:R29) -> 3.7068182 | G13: =AVERAGE(S29:V29) -> 3.8076797 | H13: =AVERAGE(W29:Z29) -> 3.7604843 | I13: =AVERAGE(AA29:AD29) -> 3.75 | J13: =AVERAGE(AE29:AH29) -> 3.75 | K13: =AVERAGE(AI29:AL29) -> 3.75
A14: Marginal 10yr Bonds Rate | C14: =AVERAGE(C30:F30) -> 3.0358333 | D14: =AVERAGE(G30:J30) -> 3.4458333 | E14: =AVERAGE(K30:N30) -> 3.2775 | F14: =AVERAGE(O30:R30) -> 3.3042592 | G14: =AVERAGE(S30:V30) -> 3.4561688 | H14: =AVERAGE(W30:Z30) -> 3.4953072 | I14: =AVERAGE(AA30:AD30) -> 3.5 | J14: =AVERAGE(AE30:AH30) -> 3.5 | K14: =AVERAGE(AI30:AL30) -> 3.5
A16: Marginal 2Y Bond Rate | C16: =AVERAGE(C32:F32) -> 3.1768667 | D16: =AVERAGE(G32:J32) -> 4.0519 | E16: =AVERAGE(K32:N32) -> 3.4922667 | F16: =AVERAGE(O32:R32) -> 2.9513889 | G16: =AVERAGE(S32:V32) -> 2.4880752 | H16: =AVERAGE(W32:Z32) -> 2.7674467 | I16: =AVERAGE(AA32:AD32) -> 2.82 | J16: =AVERAGE(AE32:AH32) -> 2.82 | K16: =AVERAGE(AI32:AL32) -> 2.82
A17: Marginal 3Y Bond Rate | C17: =AVERAGE(C33:F33) -> 3.1768667 | D17: =AVERAGE(G33:J33) -> 4.0519 | E17: =AVERAGE(K33:N33) -> 3.4922667 | F17: =AVERAGE(O33:R33) -> 2.9513889 | G17: =AVERAGE(S33:V33) -> 2.5634454 | H17: =AVERAGE(W33:Z33) -> 2.8226651 | I17: =AVERAGE(AA33:AD33) -> 2.868 | J17: =AVERAGE(AE33:AH33) -> 2.868 | K17: =AVERAGE(AI33:AL33) -> 2.868
A18: Marginal 5Y Bond Rate | C18: =AVERAGE(C34:F34) -> 3.1768667 | D18: =AVERAGE(G34:J34) -> 4.0519 | E18: =AVERAGE(K34:N34) -> 3.4922667 | F18: =AVERAGE(O34:R34) -> 2.9513889 | G18: =AVERAGE(S34:V34) -> 2.7644324 | H18: =AVERAGE(W34:Z34) -> 2.9699143 | I18: =AVERAGE(AA34:AD34) -> 2.996 | J18: =AVERAGE(AE34:AH34) -> 2.996 | K18: =AVERAGE(AI34:AL34) -> 2.996
A20: Marginal Interest Rate (MT Bonds) | C20: =SUMPRODUCT(C7:C9,C16:C18) -> 3.1768667 | D20: =SUMPRODUCT(D7:D9,D16:D18) -> 4.0519 | E20: =SUMPRODUCT(E7:E9,E16:E18) -> 3.4922667 | F20: =SUMPRODUCT(F7:F9,F16:F18) -> 2.9513889 | G20: =SUMPRODUCT(G7:G9,G16:G18) -> 2.6044361 | H20: =SUMPRODUCT(H7:H9,H16:H18) -> 2.8517559 | I20: =SUMPRODUCT(I7:I9,I16:I18) -> 2.8932879 | J20: =SUMPRODUCT(J7:J9,J16:J18) -> 2.8932879 | K20: =SUMPRODUCT(K7:K9,K16:K18) -> 2.8932879
A21: Marginal Interest Rate (All new debt) | C21: =C$2*C12+C$3*C13+C$4*C$7*C$16+C$4*C$8*C$17+C$4*C$9*C$18 -> 3.2565903 | D21: =D$2*D12+D$3*D13+D$4*D$7*D$16+D$4*D$8*D$17+D$4*D$9*D$18 -> 4.4822012 | E21: =E$2*E12+E$3*E13+E$4*E$7*E$16+E$4*E$8*E$17+E$4*E$9*E$18 -> 3.6444528 | F21: =F$2*F12+F$3*F13+F$4*F$7*F$16+F$4*F$8*F$17+F$4*F$9*F$18 -> 2.8419066 | G21: =G$2*G12+G$3*G13+G$4*G$7*G$16+G$4*G$8*G$17+G$4*G$9*G$18 -> 2.6580714 | H21: =H$2*H12+H$3*H13+H$4*H$7*H$16+H$4*H$8*H$17+H$4*H$9*H$18 -> 2.8980501 | I21: =I$2*I12+I$3*I13+I$4*I$7*I$16+I$4*I$8*I$17+I$4*I$9*I$18 -> 2.9683549 | J21: =J$2*J12+J$3*J13+J$4*J$7*J$16+J$4*J$8*J$17+J$4*J$9*J$18 -> 2.9683549 | K21: =K$2*K12+K$3*K13+K$4*K$7*K$16+K$4*K$8*K$17+K$4*K$9*K$18 -> 2.9683549
A27: Debt Model Projections (Quarterly):
B28: _date_ | C28: 44652 | D28: 44743 | E28: 44835 | F28: 44927 | G28: 45017 | H28: 45108 | I28: 45200 | J28: 45292 | K28: 45383 | L28: 45474 | M28: 45566 | N28: 45658 | O28: 45748 | P28: 45839 | Q28: 45931 | R28: 46023 | S28: 46113 | T28: 46204 | U28: 46296 | V28: 46388 | W28: 46478 | X28: 46569 | Y28: 46661 | Z28: 46753 | AA28: 46844 | AB28: 46935 | AC28: 47027 | AD28: 47119 | AE28: 47209 | AF28: 47300 | AG28: 47392 | AH28: 47484 | AI28: 47574 | AJ28: 47665 | AK28: 47757 | AL28: 47849
A29: Marginal LT Bonds Rate | B29: RGCBLTB_0 | C29: 2.92 | D29: 2.94 | E29: 3.2366667 | F29: 3.0833333 | G29: 3.0733333 | H29: 3.5233333 | I29: 3.3933333 | J29: 3.34 | K29: 3.5533333 | L29: 3.2 | M29: 3.3233333 | N29: 3.2933333 | O29: 3.53 | P29: 3.7833333 | Q29: 3.6766667 | R29: 3.837273 | S29: 3.825513 | T29: 3.813624 | U29: 3.801735 | V29: 3.789847 | W29: 3.777958 | X29: 3.763979 | Y29: 3.75 | Z29: 3.75 | AA29: 3.75 | AB29: 3.75 | AC29: 3.75 | AD29: 3.75 | AE29: 3.75 | AF29: 3.75 | AG29: 3.75 | AH29: 3.75 | AI29: 3.75 | AJ29: 3.75 | AK29: 3.75 | AL29: 3.75
A30: Marginal 10yr Bonds Rate | B30: RGCB10B_0 | C30: 2.95 | D30: 2.9866667 | E30: 3.1766667 | F30: 3.03 | G30: 3.0833333 | H30: 3.7033333 | I30: 3.56 | J30: 3.4366667 | K30: 3.67 | L30: 3.09 | M30: 3.2566667 | N30: 3.0933333 | O30: 3.21 | P30: 3.3766667 | Q30: 3.2333333 | R30: 3.397037 | S30: 3.437382 | T30: 3.449905 | U30: 3.462431 | V30: 3.474957 | W30: 3.487486 | X30: 3.493743 | Y30: 3.5 | Z30: 3.5 | AA30: 3.5 | AB30: 3.5 | AC30: 3.5 | AD30: 3.5 | AE30: 3.5 | AF30: 3.5 | AG30: 3.5 | AH30: 3.5 | AI30: 3.5 | AJ30: 3.5 | AK30: 3.5 | AL30: 3.5
A31: Marginal T-Bills Rate | B31: RTB_0 | C31: 1.6526667 | D31: 3.222 | E31: 4.2026667 | F31: 4.4763333 | G31: 4.6483333 | H31: 5.112 | I31: 5.08 | J31: 5.0036667 | K31: 4.8236667 | L31: 4.1976667 | M31: 3.4213333 | N31: 2.815 | O31: 2.6616667 | P31: 2.596 | Q31: 2.246 | R31: 2.184667 | S31: 2.2 | T31: 2.2 | U31: 2.2 | V31: 2.2 | W31: 2.45 | X31: 2.45 | Y31: 2.7 | Z31: 2.7 | AA31: 2.7 | AB31: 2.7 | AC31: 2.7 | AD31: 2.7 | AE31: 2.7 | AF31: 2.7 | AG31: 2.7 | AH31: 2.7 | AI31: 2.7 | AJ31: 2.7 | AK31: 2.7 | AL31: 2.7
A32: Marginal 2Y Bond Rate | B32: RGCB2B_0 | C32: 2.4310667 | D32: 3.0808 | E32: 3.5870667 | F32: 3.6085333 | G32: 3.7093333 | H32: 4.2668 | I32: 4.168 | J32: 4.0634667 | K32: 4.1314667 | L32: 3.5330667 | M32: 3.3225333 | N32: 2.982 | O32: 2.9906667 | P32: 3.0644 | Q32: 2.8384 | R32: 2.912089 | S32: 2.4156075 | T32: 2.4483044 | U32: 2.5111633 | V32: 2.5772257 | W32: 2.6982252 | X32: 2.7315615 | Y32: 2.82 | Z32: 2.82 | AA32: 2.82 | AB32: 2.82 | AC32: 2.82 | AD32: 2.82 | AE32: 2.82 | AF32: 2.82 | AG32: 2.82 | AH32: 2.82 | AI32: 2.82 | AJ32: 2.82 | AK32: 2.82 | AL32: 2.82
A33: Marginal 3Y Bond Rate | B33: RGCB3B_0 | C33: 2.4310667 | D33: 3.0808 | E33: 3.5870667 | F33: 3.6085333 | G33: 3.7093333 | H33: 4.2668 | I33: 4.168 | J33: 4.0634667 | K33: 4.1314667 | L33: 3.5330667 | M33: 3.3225333 | N33: 2.982 | O33: 2.9906667 | P33: 3.0644 | Q33: 2.8384 | R33: 2.912089 | S33: 2.4898505 | T33: 2.5232987 | U33: 2.5869092 | V33: 2.6537231 | W33: 2.7604744 | X33: 2.794186 | Y33: 2.868 | Z33: 2.868 | AA33: 2.868 | AB33: 2.868 | AC33: 2.868 | AD33: 2.868 | AE33: 2.868 | AF33: 2.868 | AG33: 2.868 | AH33: 2.868 | AI33: 2.868 | AJ33: 2.868 | AK33: 2.868 | AL33: 2.868
A34: Marginal 5Y Bond Rate | B34: RGCB5B_0 | C34: 2.4310667 | D34: 3.0808 | E34: 3.5870667 | F34: 3.6085333 | G34: 3.7093333 | H34: 4.2668 | I34: 4.168 | J34: 4.0634667 | K34: 4.1314667 | L34: 3.5330667 | M34: 3.3225333 | N34: 2.982 | O34: 2.9906667 | P34: 3.0644 | Q34: 2.8384 | R34: 2.912089 | S34: 2.6878316 | T34: 2.7232835 | U34: 2.7888982 | V34: 2.8577162 | W34: 2.9264721 | X34: 2.9611849 | Y34: 2.996 | Z34: 2.996 | AA34: 2.996 | AB34: 2.996 | AC34: 2.996 | AD34: 2.996 | AE34: 2.996 | AF34: 2.996 | AG34: 2.996 | AH34: 2.996 | AI34: 2.996 | AJ34: 2.996 | AK34: 2.996 | AL34: 2.996
A36: Share of LT Bonds | O36: =F3 -> 0.18739635 | P36: =O36 -> 0.18739635 | Q36: =P36 -> 0.18739635 | R36: =Q36 -> 0.18739635 | S36: =R36 -> 0.18739635 | T36: =S36 -> 0.18739635 | U36: =T36 -> 0.18739635 | V36: =U36 -> 0.18739635 | W36: =V36 -> 0.18739635 | ... AL36: =AK36 -> 0.18739635
A37: Share of T-bills | O37: =F2 -> 0.47429519 | P37: =O37 -> 0.47429519 | Q37: =P37 -> 0.47429519 | R37: =Q37 -> 0.47429519 | S37: =R37 -> 0.47429519 | T37: =S37 -> 0.47429519 | U37: =T37 -> 0.47429519 | V37: =U37 -> 0.47429519 | W37: =V37 -> 0.47429519 | ... AL37: =AK37 -> 0.47429519
A38: Share of 2Y Bonds | O38: =F4*F7 -> 0.19900498 | P38: =O38 -> 0.19900498 | Q38: =P38 -> 0.19900498 | R38: =Q38 -> 0.19900498 | S38: =R38 -> 0.19900498 | T38: =S38 -> 0.19900498 | U38: =T38 -> 0.19900498 | V38: =U38 -> 0.19900498 | W38: =V38 -> 0.19900498 | ... AL38: =AK38 -> 0.19900498
A39: Share of 3Y Bonds | O39: =F4*F8 -> 0 | P39: =O39 -> 0 | Q39: =P39 -> 0 | R39: =Q39 -> 0 | S39: =R39 -> 0 | T39: =S39 -> 0 | U39: =T39 -> 0 | V39: =U39 -> 0 | W39: =V39 -> 0 | ... AL39: =AK39 -> 0
A40: Share of 5Y Bonds | O40: =F4*F9 -> 0.13930348 | P40: =O40 -> 0.13930348 | Q40: =P40 -> 0.13930348 | R40: =Q40 -> 0.13930348 | S40: =R40 -> 0.13930348 | T40: =S40 -> 0.13930348 | U40: =T40 -> 0.13930348 | V40: =U40 -> 0.13930348 | W40: =V40 -> 0.13930348 | ... AL40: =AK40 -> 0.13930348
A42: Marginal interest rate (all new debt) | O42: =O29*O36+SUMPRODUCT(O31:O34,O37:O40) -> 2.9356926 | P42: =P29*P36+SUMPRODUCT(P31:P34,P37:P40) -> 2.9769656 | Q42: =Q29*Q36+SUMPRODUCT(Q31:Q34,Q37:Q40) -> 2.7145156 | R42: =R29*R36+SUMPRODUCT(R31:R34,R37:R40) -> 2.7404523 | S42: =S29*S36+SUMPRODUCT(S31:S34,S37:S40) -> 2.6154788 | T42: =T29*T36+SUMPRODUCT(T31:T34,T37:T40) -> 2.6246963 | U42: =U29*U36+SUMPRODUCT(U31:U34,U37:U40) -> 2.6441179 | V42: =V29*V36+SUMPRODUCT(V31:V34,V37:V40) -> 2.6646235 | ... AL42: =AL29*AL36+SUMPRODUCT(AL31:AL34,AL37:AL40) -> 2.9618806
A44: Share of 3-month T-bills | O44: =O37 -> 0.47429519 | P44: =O44 -> 0.47429519 | Q44: =P44 -> 0.47429519 | R44: =Q44 -> 0.47429519 | S44: =R44 -> 0.47429519 | T44: =S44 -> 0.47429519 | U44: =T44 -> 0.47429519 | V44: =U44 -> 0.47429519 | W44: =V44 -> 0.47429519 | ... AL44: =AK44 -> 0.47429519
